# 연습문제 Ch8-6

### 문제

아래의 코드가 수행되었을 때의 실행결과를 적으시오.

```java
class Exercise8_6 {
    public static void main(String[] args) {
        try {
            method1();
        } catch(Exception e) {
            System.out.println(5);
        }
    }
    static void method1() {
        try {
            method2();
            System.out.println(1);
        } catch(ArithmeticException e) {
            System.out.println(2);
        } finally {
            System.out.println(3);
        }
        System.out.println(4);
    } // method1()
    static void method2() {
        throw new NullPointerException();
    }
}
```

### 나의 풀이

3

5

method2에서 에러 발생 후 종료된다. method1에서 에러를 이어받아 try-catch에서 해결하려고 하지만 catch문에서 해당되는 에러가 없기 때문에 처리하지 못하고 그대로 method1이 종료된다. 이때 finally는 실행된다. main으로 에러가 넘어가서 catch문에서 에러가 해결된다.