# 연습문제 Ch8-5

### 문제

아래의 코드가 수행되었을 때의 실행결과를 적으시오.

```java
class Exercise8_5 {
	static void method(boolean b) {
			try {
					System.out.println(1);
					if(b) throw new ArithmeticException();
					System.out.println(2);
			} catch(RuntimeException r) {
					System.out.println(3);
					return;
			} catch(Exception e) {
						System.out.println(4);
						return;
			} finally {
						System.out.println(5);
			}
			System.out.println(6);
	}
        public static void main(String[] args) {
                    method(true);
                    method(false);
                } // main
        }
```

### 나의풀이

1

3

5

1

2

5

6

ArithmeticException은 RuntimeException 의 자손이므로  RuntimeException 이 정의된
catch 블럭에서 처리된다 이 catch 블럭에 return문이 있으므로 메서드를 종료하고 빠져나
가게 된다